Workbook
Name Ejercicio_fiscal: #REF!
Name RAZÓN_SOCIAL: #REF!
Name RUC: #REF!

Sheet BC
A1: =RAZÓN_SOCIAL -> #REF!
A2: Balance de comprobación
A3: =Ejercicio_fiscal -> #REF! | U3: =SUM(U7:U347) -> 0
D4: Saldo | K4: Saldo ajustado
A5: Item # | B5: Código Cuenta | C5: Cuenta | D5: Año 2020 | E5: casillero | F5: Grupo | G5: nombre cuenta formulario 101 | H5: Mapeo EF | I5: Débito | J5: Crédito | K5: =CONCATENATE("Año ",RIGHT(Ejercicio_fiscal,4)) -> #REF! | L5: Sin mapear | M5: Observaciones
B6: Es importante que la información se ingrese solo en las celdas BLANCAS. Todas las demás celdas calcularán automáticamente en función de la información ingresada en las celdas BLANCAS. | D6: =SUM(D7:D347) -> #REF! | I6: =SUM(I7:I347) -> #REF! | J6: =SUM(J7:J347) -> #REF! | K6: =SUM(K7:K347) -> #REF! | L6: =SUM(L7:L347) -> #REF!
A7: =ROW(A7)-7 -> 0 | B7: 1.01.01.01.01 | C7: CAJA GENERAL | D7: =+#REF! -> #REF! | E7: 311 | F7: =IFERROR(VLOOKUP($E7,Casilleros!$A$4:$I$830,4,FALSE),"") -> ACTIVOS CORRIENTES | G7: =IFERROR(VLOOKUP($E7,Casilleros!$A$4:$I$830,9,FALSE),"") -> Efectivo y equivalentes al efectivo | H7: =IFERROR(VLOOKUP($E7,Casilleros!$A$4:$J$830,10,FALSE),"") -> Efectivo y equivalentes al efectivo | I7: =SUMIF(#REF!,$B7,#REF!) -> #REF! | J7: =SUMIF(#REF!,$B7,#REF!) -> #REF! | K7: =+D7+SUM(I7:J7) -> #REF! | L7: =IF(E7="",K7,0) -> 0
A8: =ROW(A8)-7 -> 1 | B8: 1.01.01.01.02 | C8: CAJA CHICA | D8: =+#REF! -> #REF! | E8: 311 | F8: =IFERROR(VLOOKUP($E8,Casilleros!$A$4:$I$830,4,FALSE),"") -> ACTIVOS CORRIENTES | G8: =IFERROR(VLOOKUP($E8,Casilleros!$A$4:$I$830,9,FALSE),"") -> Efectivo y equivalentes al efectivo | H8: =IFERROR(VLOOKUP($E8,Casilleros!$A$4:$J$830,10,FALSE),"") -> Efectivo y equivalentes al efectivo | I8: =SUMIF(#REF!,$B8,#REF!) -> #REF! | J8: =SUMIF(#REF!,$B8,#REF!) -> #REF! | K8: =+D8+SUM(I8:J8) -> #REF! | L8: =IF(E8="",K8,0) -> 0
A9: =ROW(A9)-7 -> 2 | B9: 1.01.01.01.08 | C9: CAJA-TARJETA DIFERIDOS #2 | D9: =+#REF! -> #REF! | E9: 311 | F9: =IFERROR(VLOOKUP($E9,Casilleros!$A$4:$I$830,4,FALSE),"") -> ACTIVOS CORRIENTES | G9: =IFERROR(VLOOKUP($E9,Casilleros!$A$4:$I$830,9,FALSE),"") -> Efectivo y equivalentes al efectivo | H9: =IFERROR(VLOOKUP($E9,Casilleros!$A$4:$J$830,10,FALSE),"") -> Efectivo y equivalentes al efectivo | I9: =SUMIF(#REF!,$B9,#REF!) -> #REF! | J9: =SUMIF(#REF!,$B9,#REF!) -> #REF! | K9: =+D9+SUM(I9:J9) -> #REF! | L9: =IF(E9="",K9,0) -> 0
A10: =ROW(A10)-7 -> 3 | B10: 1.01.01.01.08 | C10: CAJA-TARJETA DIFERIDOS #2 | D10: =+#REF! -> #REF! | E10: 311 | F10: =IFERROR(VLOOKUP($E10,Casilleros!$A$4:$I$830,4,FALSE),"") -> ACTIVOS CORRIENTES | G10: =IFERROR(VLOOKUP($E10,Casilleros!$A$4:$I$830,9,FALSE),"") -> Efectivo y equivalentes al efectivo | H10: =IFERROR(VLOOKUP($E10,Casilleros!$A$4:$J$830,10,FALSE),"") -> Efectivo y equivalentes al efectivo | I10: =SUMIF(#REF!,$B10,#REF!) -> #REF! | J10: =SUMIF(#REF!,$B10,#REF!) -> #REF! | K10: =+D10+SUM(I10:J10) -> #REF! | L10: =IF(E10="",K10,0) -> 0
A11: =ROW(A11)-7 -> 4 | B11: 1.01.01.02.02 | C11: PRODUBANCO CTA.CTE.01-04918600-3 | D11: =+#REF! -> #REF! | E11: 311 | F11: =IFERROR(VLOOKUP($E11,Casilleros!$A$4:$I$830,4,FALSE),"") -> ACTIVOS CORRIENTES | G11: =IFERROR(VLOOKUP($E11,Casilleros!$A$4:$I$830,9,FALSE),"") -> Efectivo y equivalentes al efectivo | H11: =IFERROR(VLOOKUP($E11,Casilleros!$A$4:$J$830,10,FALSE),"") -> Efectivo y equivalentes al efectivo | I11: =SUMIF(#REF!,$B11,#REF!) -> #REF! | J11: =SUMIF(#REF!,$B11,#REF!) -> #REF! | K11: =+D11+SUM(I11:J11) -> #REF! | L11: =IF(E11="",K11,0) -> 0
A12: =ROW(A12)-7 -> 5 | B12: 1.01.01.02.03 | C12: BANCO BOLIVARIANO CTA CTE 5025022482 | D12: =+#REF! -> #REF! | E12: 311 | F12: =IFERROR(VLOOKUP($E12,Casilleros!$A$4:$I$830,4,FALSE),"") -> ACTIVOS CORRIENTES | G12: =IFERROR(VLOOKUP($E12,Casilleros!$A$4:$I$830,9,FALSE),"") -> Efectivo y equivalentes al efectivo | H12: =IFERROR(VLOOKUP($E12,Casilleros!$A$4:$J$830,10,FALSE),"") -> Efectivo y equivalentes al efectivo | I12: =SUMIF(#REF!,$B12,#REF!) -> #REF! | J12: =SUMIF(#REF!,$B12,#REF!) -> #REF! | K12: =+D12+SUM(I12:J12) -> #REF! | L12: =IF(E12="",K12,0) -> 0
A13: =ROW(A13)-7 -> 6 | B13: 1.01.01.02.04 | C13: BOLIVARIANO INTERNACIONAL PANAMA - 01302005222 | D13: =+#REF! -> #REF! | E13: 311 | F13: =IFERROR(VLOOKUP($E13,Casilleros!$A$4:$I$830,4,FALSE),"") -> ACTIVOS CORRIENTES | G13: =IFERROR(VLOOKUP($E13,Casilleros!$A$4:$I$830,9,FALSE),"") -> Efectivo y equivalentes al efectivo | H13: =IFERROR(VLOOKUP($E13,Casilleros!$A$4:$J$830,10,FALSE),"") -> Efectivo y equivalentes al efectivo | I13: =SUMIF(#REF!,$B13,#REF!) -> #REF! | J13: =SUMIF(#REF!,$B13,#REF!) -> #REF! | K13: =+D13+SUM(I13:J13) -> #REF! | L13: =IF(E13="",K13,0) -> 0
A14: =ROW(A14)-7 -> 7 | B14: 1.01.01.02.06 | C14: GUAYAQUIL CTA CTE 49802005 | D14: =+#REF! -> #REF! | E14: 311 | F14: =IFERROR(VLOOKUP($E14,Casilleros!$A$4:$I$830,4,FALSE),"") -> ACTIVOS CORRIENTES | G14: =IFERROR(VLOOKUP($E14,Casilleros!$A$4:$I$830,9,FALSE),"") -> Efectivo y equivalentes al efectivo | H14: =IFERROR(VLOOKUP($E14,Casilleros!$A$4:$J$830,10,FALSE),"") -> Efectivo y equivalentes al efectivo | I14: =SUMIF(#REF!,$B14,#REF!) -> #REF! | J14: =SUMIF(#REF!,$B14,#REF!) -> #REF! | K14: =+D14+SUM(I14:J14) -> #REF! | L14: =IF(E14="",K14,0) -> 0
A15: =ROW(A15)-7 -> 8 | B15: =+#REF! -> #REF! | C15: =+#REF! -> #REF! | D15: =+#REF! -> #REF! | E15: 311 | F15: =IFERROR(VLOOKUP($E15,Casilleros!$A$4:$I$830,4,FALSE),"") -> ACTIVOS CORRIENTES | G15: =IFERROR(VLOOKUP($E15,Casilleros!$A$4:$I$830,9,FALSE),"") -> Efectivo y equivalentes al efectivo | H15: =IFERROR(VLOOKUP($E15,Casilleros!$A$4:$J$830,10,FALSE),"") -> Efectivo y equivalentes al efectivo | I15: =SUMIF(#REF!,$B15,#REF!) -> #REF! | J15: =SUMIF(#REF!,$B15,#REF!) -> #REF! | K15: =+D15+SUM(I15:J15) -> #REF! | L15: =IF(E15="",K15,0) -> 0
A16: =ROW(A16)-7 -> 9 | B16: 1.01.01.03.01 | C16: INVERSIONES BCO GUAYAQUIL | D16: =+#REF! -> #REF! | E16: 311 | F16: =IFERROR(VLOOKUP($E16,Casilleros!$A$4:$I$830,4,FALSE),"") -> ACTIVOS CORRIENTES | G16: =IFERROR(VLOOKUP($E16,Casilleros!$A$4:$I$830,9,FALSE),"") -> Efectivo y equivalentes al efectivo | H16: =IFERROR(VLOOKUP($E16,Casilleros!$A$4:$J$830,10,FALSE),"") -> Efectivo y equivalentes al efectivo | I16: =SUMIF(#REF!,$B16,#REF!) -> #REF! | J16: =SUMIF(#REF!,$B16,#REF!) -> #REF! | K16: =+D16+SUM(I16:J16) -> #REF! | L16: =IF(E16="",K16,0) -> 0
A17: =ROW(A17)-7 -> 10 | B17: 1.01.01.03.02 | C17: INVERSIONES PRODUBANCO | D17: =+#REF! -> #REF! | E17: 311 | F17: =IFERROR(VLOOKUP($E17,Casilleros!$A$4:$I$830,4,FALSE),"") -> ACTIVOS CORRIENTES | G17: =IFERROR(VLOOKUP($E17,Casilleros!$A$4:$I$830,9,FALSE),"") -> Efectivo y equivalentes al efectivo | H17: =IFERROR(VLOOKUP($E17,Casilleros!$A$4:$J$830,10,FALSE),"") -> Efectivo y equivalentes al efectivo | I17: =SUMIF(#REF!,$B17,#REF!) -> #REF! | J17: =SUMIF(#REF!,$B17,#REF!) -> #REF! | K17: =+D17+SUM(I17:J17) -> #REF! | L17: =IF(E17="",K17,0) -> 0
A18: =ROW(A18)-7 -> 11 | B18: 1.01.02.05.01 | C18: CLIENTES | D18: =+#REF! -> #REF! | E18: 315 | F18: =IFERROR(VLOOKUP($E18,Casilleros!$A$4:$I$830,4,FALSE),"") -> ACTIVOS CORRIENTES | G18: =IFERROR(VLOOKUP($E18,Casilleros!$A$4:$I$830,9,FALSE),"") -> CUENTAS Y DOCUMENTOS POR COBRAR CORRIENTES_CUENTAS Y DOCUMENTOS POR COBRAR COMERCIALES CORRIENTES_NO RELACIONADAS_Locales | H18: =IFERROR(VLOOKUP($E18,Casilleros!$A$4:$J$830,10,FALSE),"") -> Cuentas y Documentos por cobrar corrientes | I18: =SUMIF(#REF!,$B18,#REF!) -> #REF! | J18: =SUMIF(#REF!,$B18,#REF!) -> #REF! | K18: =+D18+SUM(I18:J18) -> #REF! | L18: =IF(E18="",K18,0) -> 0
A19: =ROW(A19)-7 -> 12 | B19: 1.01.02.05.99 | C19: DETERIORO CUENTAS PO COBRAR | D19: =+#REF! -> #REF! | E19: 317 | F19: =IFERROR(VLOOKUP($E19,Casilleros!$A$4:$I$830,4,FALSE),"") -> ACTIVOS CORRIENTES | G19: =IFERROR(VLOOKUP($E19,Casilleros!$A$4:$I$830,9,FALSE),"") -> CUENTAS Y DOCUMENTOS POR COBRAR CORRIENTES_CUENTAS Y DOCUMENTOS POR COBRAR COMERCIALES CORRIENTES_NO RELACIONADAS_(-) Deterioro acumulado del valor de cuentas y documentos por cobrar comerciales por incobrabilidad (provisiones para créditos incobrables) | H19: =IFERROR(VLOOKUP($E19,Casilleros!$A$4:$J$830,10,FALSE),"") -> Cuentas y Documentos por cobrar corrientes | I19: =SUMIF(#REF!,$B19,#REF!) -> #REF! | J19: =SUMIF(#REF!,$B19,#REF!) -> #REF! | K19: =+D19+SUM(I19:J19) -> #REF! | L19: =IF(E19="",K19,0) -> 0
A20: =ROW(A20)-7 -> 13 | B20: 1.01.02.07.01 | C20: CHEQUES PROTESTADOS | D20: =+#REF! -> #REF! | E20: 315 | F20: =IFERROR(VLOOKUP($E20,Casilleros!$A$4:$I$830,4,FALSE),"") -> ACTIVOS CORRIENTES | G20: =IFERROR(VLOOKUP($E20,Casilleros!$A$4:$I$830,9,FALSE),"") -> CUENTAS Y DOCUMENTOS POR COBRAR CORRIENTES_CUENTAS Y DOCUMENTOS POR COBRAR COMERCIALES CORRIENTES_NO RELACIONADAS_Locales | H20: =IFERROR(VLOOKUP($E20,Casilleros!$A$4:$J$830,10,FALSE),"") -> Cuentas y Documentos por cobrar corrientes | I20: =SUMIF(#REF!,$B20,#REF!) -> #REF! | J20: =SUMIF(#REF!,$B20,#REF!) -> #REF! | K20: =+D20+SUM(I20:J20) -> #REF! | L20: =IF(E20="",K20,0) -> 0
A21: =ROW(A21)-7 -> 14 | B21: 1.01.02.08.01 | C21: OTRAS CUENTAS POR COBRAR A TERCEROS | D21: =+#REF! -> #REF! | E21: 325 | F21: =IFERROR(VLOOKUP($E21,Casilleros!$A$4:$I$830,4,FALSE),"") -> ACTIVOS CORRIENTES | G21: =IFERROR(VLOOKUP($E21,Casilleros!$A$4:$I$830,9,FALSE),"") -> CUENTAS Y DOCUMENTOS POR COBRAR CORRIENTES_OTRAS CUENTAS Y DOCUMENTOS POR COBRAR CORRIENTES_OTRAS NO RELACIONADAS_Locales | H21: =IFERROR(VLOOKUP($E21,Casilleros!$A$4:$J$830,10,FALSE),"") -> Cuentas y Documentos por cobrar corrientes | I21: =SUMIF(#REF!,$B21,#REF!) -> #REF! | J21: =SUMIF(#REF!,$B21,#REF!) -> #REF! | K21: =+D21+SUM(I21:J21) -> #REF! | L21: =IF(E21="",K21,0) -> 0
A22: =ROW(A22)-7 -> 15 | B22: 1.01.02.08.02 | C22: ANTICIPO EMPLEADOS | D22: =+#REF! -> #REF! | E22: 325 | F22: =IFERROR(VLOOKUP($E22,Casilleros!$A$4:$I$830,4,FALSE),"") -> ACTIVOS CORRIENTES | G22: =IFERROR(VLOOKUP($E22,Casilleros!$A$4:$I$830,9,FALSE),"") -> CUENTAS Y DOCUMENTOS POR COBRAR CORRIENTES_OTRAS CUENTAS Y DOCUMENTOS POR COBRAR CORRIENTES_OTRAS NO RELACIONADAS_Locales | H22: =IFERROR(VLOOKUP($E22,Casilleros!$A$4:$J$830,10,FALSE),"") -> Cuentas y Documentos por cobrar corrientes | I22: =SUMIF(#REF!,$B22,#REF!) -> #REF! | J22: =SUMIF(#REF!,$B22,#REF!) -> #REF! | K22: =+D22+SUM(I22:J22) -> #REF! | L22: =IF(E22="",K22,0) -> 0
A23: =ROW(A23)-7 -> 16 | B23: 1.01.02.08.03 | C23: ANTICIPO SUELDOS | E23: 325 | F23: =IFERROR(VLOOKUP($E23,Casilleros!$A$4:$I$830,4,FALSE),"") -> ACTIVOS CORRIENTES | G23: =IFERROR(VLOOKUP($E23,Casilleros!$A$4:$I$830,9,FALSE),"") -> CUENTAS Y DOCUMENTOS POR COBRAR CORRIENTES_OTRAS CUENTAS Y DOCUMENTOS POR COBRAR CORRIENTES_OTRAS NO RELACIONADAS_Locales | H23: =IFERROR(VLOOKUP($E23,Casilleros!$A$4:$J$830,10,FALSE),"") -> Cuentas y Documentos por cobrar corrientes | I23: =SUMIF(#REF!,$B23,#REF!) -> #REF! | J23: =SUMIF(#REF!,$B23,#REF!) -> #REF! | K23: =+D23+SUM(I23:J23) -> #REF! | L23: =IF(E23="",K23,0) -> 0
A24: =ROW(A24)-7 -> 17 | B24: 1.01.04.03 | C24: ANTICIPOS A PROVEEDORES | D24: =+#REF! -> #REF! | E24: 325 | F24: =IFERROR(VLOOKUP($E24,Casilleros!$A$4:$I$830,4,FALSE),"") -> ACTIVOS CORRIENTES | G24: =IFERROR(VLOOKUP($E24,Casilleros!$A$4:$I$830,9,FALSE),"") -> CUENTAS Y DOCUMENTOS POR COBRAR CORRIENTES_OTRAS CUENTAS Y DOCUMENTOS POR COBRAR CORRIENTES_OTRAS NO RELACIONADAS_Locales | H24: =IFERROR(VLOOKUP($E24,Casilleros!$A$4:$J$830,10,FALSE),"") -> Cuentas y Documentos por cobrar corrientes | I24: =SUMIF(#REF!,$B24,#REF!) -> #REF! | J24: =SUMIF(#REF!,$B24,#REF!) -> #REF! | K24: =+D24+SUM(I24:J24) -> #REF! | L24: =IF(E24="",K24,0) -> 0
A25: =ROW(A25)-7 -> 18 | B25: =+#REF! -> #REF! | C25: =+#REF! -> #REF! | D25: =+#REF! -> #REF! | E25: 360 | F25: =IFERROR(VLOOKUP($E25,Casilleros!$A$4:$I$830,4,FALSE),"") -> ACTIVOS CORRIENTES | G25: =IFERROR(VLOOKUP($E25,Casilleros!$A$4:$I$830,9,FALSE),"") -> Otros Activos Corrientes | H25: =IFERROR(VLOOKUP($E25,Casilleros!$A$4:$J$830,10,FALSE),"") -> Otros activos corrientes | I25: =SUMIF(#REF!,$B25,#REF!) -> #REF! | J25: =SUMIF(#REF!,$B25,#REF!) -> #REF! | K25: =+D25+SUM(I25:J25) -> #REF! | L25: =IF(E25="",K25,0) -> 0
A26: =ROW(A26)-7 -> 19 | B26: 1.01.05.02 | C26: (IR) CRÉDITO TRIBUTARIO A FAVOR DE LA EMPRESA ( I. R.) | D26: 0 | E26: 337 | F26: =IFERROR(VLOOKUP($E26,Casilleros!$A$4:$I$830,4,FALSE),"") -> ACTIVOS CORRIENTES | G26: =IFERROR(VLOOKUP($E26,Casilleros!$A$4:$I$830,9,FALSE),"") -> ACTIVOS POR IMPUESTOS CORRIENTES_Crédito tributario a favor del sujeto pasivo (Impuesto a la Renta) __ | H26: =IFERROR(VLOOKUP($E26,Casilleros!$A$4:$J$830,10,FALSE),"") -> Activos por impuestos corrientes | I26: =SUMIF(#REF!,$B26,#REF!) -> #REF! | J26: =SUMIF(#REF!,$B26,#REF!) -> #REF! | K26: =+D26+SUM(I26:J26) -> #REF! | L26: =IF(E26="",K26,0) -> 0
A27: =ROW(A27)-7 -> 20 | B27: 1.02.01.01.01 | C27: TERRENOS | D27: =+#REF! -> #REF! | E27: 362 | F27: =IFERROR(VLOOKUP($E27,Casilleros!$A$4:$I$830,4,FALSE),"") -> ACTIVOS NO CORRIENTES | G27: =IFERROR(VLOOKUP($E27,Casilleros!$A$4:$I$830,9,FALSE),"") -> PROPIEDADES, PLANTA Y EQUIPO_TERRENOS_Costo histórico antes de reexpresiones o revaluaciones_ | H27: =IFERROR(VLOOKUP($E27,Casilleros!$A$4:$J$830,10,FALSE),"") -> Propiedades, planta y equipo | I27: =SUMIF(#REF!,$B27,#REF!) -> #REF! | J27: =SUMIF(#REF!,$B27,#REF!) -> #REF! | K27: =+D27+SUM(I27:J27) -> #REF! | L27: =IF(E27="",K27,0) -> 0
A28: =ROW(A28)-7 -> 21 | B28: 1.02.01.01.02 | C28: CANCHA SINTETICA | D28: =+#REF! -> #REF! | E28: 364 | F28: =IFERROR(VLOOKUP($E28,Casilleros!$A$4:$I$830,4,FALSE),"") -> ACTIVOS NO CORRIENTES | G28: =IFERROR(VLOOKUP($E28,Casilleros!$A$4:$I$830,9,FALSE),"") -> PROPIEDADES, PLANTA Y EQUIPO_EDIFICIOS Y OTROS INMUEBLES (EXCEPTO TERRENOS)_Costo histórico antes de reexpresiones o revaluaciones _ | H28: =IFERROR(VLOOKUP($E28,Casilleros!$A$4:$J$830,10,FALSE),"") -> Propiedades, planta y equipo | I28: =SUMIF(#REF!,$B28,#REF!) -> #REF! | J28: =SUMIF(#REF!,$B28,#REF!) -> #REF! | K28: =+D28+SUM(I28:J28) -> #REF! | L28: =IF(E28="",K28,0) -> 0
A29: =ROW(A29)-7 -> 22 | B29: 1.02.01.01.03 | C29: EDIFICIOS | D29: =+#REF! -> #REF! | E29: 364 | F29: =IFERROR(VLOOKUP($E29,Casilleros!$A$4:$I$830,4,FALSE),"") -> ACTIVOS NO CORRIENTES | G29: =IFERROR(VLOOKUP($E29,Casilleros!$A$4:$I$830,9,FALSE),"") -> PROPIEDADES, PLANTA Y EQUIPO_EDIFICIOS Y OTROS INMUEBLES (EXCEPTO TERRENOS)_Costo histórico antes de reexpresiones o revaluaciones _ | H29: =IFERROR(VLOOKUP($E29,Casilleros!$A$4:$J$830,10,FALSE),"") -> Propiedades, planta y equipo | I29: =SUMIF(#REF!,$B29,#REF!) -> #REF! | J29: =SUMIF(#REF!,$B29,#REF!) -> #REF! | K29: =+D29+SUM(I29:J29) -> #REF! | L29: =IF(E29="",K29,0) -> 0
A30: =ROW(A30)-7 -> 23 | B30: 1.02.01.01.05 | C30: MUEBLES Y ENSERES | D30: =+#REF! -> #REF! | E30: 373 | F30: =IFERROR(VLOOKUP($E30,Casilleros!$A$4:$I$830,4,FALSE),"") -> ACTIVOS NO CORRIENTES | G30: =IFERROR(VLOOKUP($E30,Casilleros!$A$4:$I$830,9,FALSE),"") -> PROPIEDADES, PLANTA Y EQUIPO_Muebles y enseres__ | H30: =IFERROR(VLOOKUP($E30,Casilleros!$A$4:$J$830,10,FALSE),"") -> Propiedades, planta y equipo | I30: =SUMIF(#REF!,$B30,#REF!) -> #REF! | J30: =SUMIF(#REF!,$B30,#REF!) -> #REF! | K30: =+D30+SUM(I30:J30) -> #REF! | L30: =IF(E30="",K30,0) -> 0
A31: =ROW(A31)-7 -> 24 | B31: 1.02.01.01.06 | C31: MAQUINARIA Y EQUIPO | D31: =+#REF! -> #REF! | E31: 368 | F31: =IFERROR(VLOOKUP($E31,Casilleros!$A$4:$I$830,4,FALSE),"") -> ACTIVOS NO CORRIENTES | G31: =IFERROR(VLOOKUP($E31,Casilleros!$A$4:$I$830,9,FALSE),"") -> PROPIEDADES, PLANTA Y EQUIPO_MAQUINARIA, EQUIPO, INSTALACIONES Y ADECUACIONES_Costo histórico antes de reexpresiones o revaluaciones _ | H31: =IFERROR(VLOOKUP($E31,Casilleros!$A$4:$J$830,10,FALSE),"") -> Propiedades, planta y equipo | I31: =SUMIF(#REF!,$B31,#REF!) -> #REF! | J31: =SUMIF(#REF!,$B31,#REF!) -> #REF! | K31: =+D31+SUM(I31:J31) -> #REF! | L31: =IF(E31="",K31,0) -> 0
A32: =ROW(A32)-7 -> 25 | B32: 1.02.01.01.08 | C32: EQUIPO DE COMPUTACIÓN | D32: =+#REF! -> #REF! | E32: 374 | F32: =IFERROR(VLOOKUP($E32,Casilleros!$A$4:$I$830,4,FALSE),"") -> ACTIVOS NO CORRIENTES | G32: =IFERROR(VLOOKUP($E32,Casilleros!$A$4:$I$830,9,FALSE),"") -> PROPIEDADES, PLANTA Y EQUIPO_Equipo de Computación__equipo de computación | H32: =IFERROR(VLOOKUP($E32,Casilleros!$A$4:$J$830,10,FALSE),"") -> Propiedades, planta y equipo | I32: =SUMIF(#REF!,$B32,#REF!) -> #REF! | J32: =SUMIF(#REF!,$B32,#REF!) -> #REF! | K32: =+D32+SUM(I32:J32) -> #REF! | L32: =IF(E32="",K32,0) -> 0
A33: =ROW(A33)-7 -> 26 | B33: 1.02.01.01.09 | C33: VEHÍCULOS, EQUIPOS DE TRANSPORTE Y EQUIPO CAMINERO MÓVIL | D33: =+#REF! -> #REF! | E33: 375 | F33: =IFERROR(VLOOKUP($E33,Casilleros!$A$4:$I$830,4,FALSE),"") -> ACTIVOS NO CORRIENTES | G33: =IFERROR(VLOOKUP($E33,Casilleros!$A$4:$I$830,9,FALSE),"") -> PROPIEDADES, PLANTA Y EQUIPO_Vehículos, Equipo de Transporte y Caminero Móvil__equipo de computación | H33: =IFERROR(VLOOKUP($E33,Casilleros!$A$4:$J$830,10,FALSE),"") -> Propiedades, planta y equipo | I33: =SUMIF(#REF!,$B33,#REF!) -> #REF! | J33: =SUMIF(#REF!,$B33,#REF!) -> #REF! | K33: =+D33+SUM(I33:J33) -> #REF! | L33: =IF(E33="",K33,0) -> 0
A34: =ROW(A34)-7 -> 27 | B34: 1.02.01.01.11 | C34: COSTO EQUIPOS | D34: =+#REF! -> #REF! | E34: 374 | F34: =IFERROR(VLOOKUP($E34,Casilleros!$A$4:$I$830,4,FALSE),"") -> ACTIVOS NO CORRIENTES | G34: =IFERROR(VLOOKUP($E34,Casilleros!$A$4:$I$830,9,FALSE),"") -> PROPIEDADES, PLANTA Y EQUIPO_Equipo de Computación__equipo de computación | H34: =IFERROR(VLOOKUP($E34,Casilleros!$A$4:$J$830,10,FALSE),"") -> Propiedades, planta y equipo | I34: =SUMIF(#REF!,$B34,#REF!) -> #REF! | J34: =SUMIF(#REF!,$B34,#REF!) -> #REF! | K34: =+D34+SUM(I34:J34) -> #REF! | L34: =IF(E34="",K34,0) -> 0
A35: =ROW(A35)-7 -> 28 | B35: 1.02.01.01.11 | C35: COSTO EQUIPOS | D35: =+#REF! -> #REF! | E35: 372 | F35: =IFERROR(VLOOKUP($E35,Casilleros!$A$4:$I$830,4,FALSE),"") -> ACTIVOS NO CORRIENTES | G35: =IFERROR(VLOOKUP($E35,Casilleros!$A$4:$I$830,9,FALSE),"") -> PROPIEDADES, PLANTA Y EQUIPO_Construcciones en Curso y Otros Activos en Tránsito__ | H35: =IFERROR(VLOOKUP($E35,Casilleros!$A$4:$J$830,10,FALSE),"") -> Propiedades, planta y equipo | I35: =SUMIF(#REF!,$B35,#REF!) -> #REF! | J35: =SUMIF(#REF!,$B35,#REF!) -> #REF! | K35: =+D35+SUM(I35:J35) -> #REF! | L35: =IF(E35="",K35,0) -> 0
A36: =ROW(A36)-7 -> 29 | B36: 1.02.01.12.01 | C36: DEPRECIACION EDIFICIOS | D36: =+#REF! -> #REF! | E36: 384 | F36: =IFERROR(VLOOKUP($E36,Casilleros!$A$4:$I$830,4,FALSE),"") -> ACTIVOS NO CORRIENTES | G36: =IFERROR(VLOOKUP($E36,Casilleros!$A$4:$I$830,9,FALSE),"") -> PROPIEDADES, PLANTA Y EQUIPO_(-) DEPRECIACIÒN ACUMULADA DE PROPIEDADES, PLANTA Y EQUIPO_Del costo histórico antes de reexpresiones o revaluaciones_ | H36: =IFERROR(VLOOKUP($E36,Casilleros!$A$4:$J$830,10,FALSE),"") -> Propiedades, planta y equipo | I36: =SUMIF(#REF!,$B36,#REF!) -> #REF! | J36: =SUMIF(#REF!,$B36,#REF!) -> #REF! | K36: =+D36+SUM(I36:J36) -> #REF! | L36: =IF(E36="",K36,0) -> 0
A37: =ROW(A37)-7 -> 30 | B37: 1.02.01.12.02 | C37: DEPRECIACION MUEBLES Y ENSERES | D37: =+#REF! -> #REF! | E37: 384 | F37: =IFERROR(VLOOKUP($E37,Casilleros!$A$4:$I$830,4,FALSE),"") -> ACTIVOS NO CORRIENTES | G37: =IFERROR(VLOOKUP($E37,Casilleros!$A$4:$I$830,9,FALSE),"") -> PROPIEDADES, PLANTA Y EQUIPO_(-) DEPRECIACIÒN ACUMULADA DE PROPIEDADES, PLANTA Y EQUIPO_Del costo histórico antes de reexpresiones o revaluaciones_ | H37: =IFERROR(VLOOKUP($E37,Casilleros!$A$4:$J$830,10,FALSE),"") -> Propiedades, planta y equipo | I37: =SUMIF(#REF!,$B37,#REF!) -> #REF! | J37: =SUMIF(#REF!,$B37,#REF!) -> #REF! | K37: =+D37+SUM(I37:J37) -> #REF! | L37: =IF(E37="",K37,0) -> 0
A38: =ROW(A38)-7 -> 31 | B38: 1.02.01.12.03 | C38: DEPRECIACION MAQUINARIA Y EQUIPOS | D38: =+#REF! -> #REF! | E38: 384 | F38: =IFERROR(VLOOKUP($E38,Casilleros!$A$4:$I$830,4,FALSE),"") -> ACTIVOS NO CORRIENTES | G38: =IFERROR(VLOOKUP($E38,Casilleros!$A$4:$I$830,9,FALSE),"") -> PROPIEDADES, PLANTA Y EQUIPO_(-) DEPRECIACIÒN ACUMULADA DE PROPIEDADES, PLANTA Y EQUIPO_Del costo histórico antes de reexpresiones o revaluaciones_ | H38: =IFERROR(VLOOKUP($E38,Casilleros!$A$4:$J$830,10,FALSE),"") -> Propiedades, planta y equipo | I38: =SUMIF(#REF!,$B38,#REF!) -> #REF! | J38: =SUMIF(#REF!,$B38,#REF!) -> #REF! | K38: =+D38+SUM(I38:J38) -> #REF! | L38: =IF(E38="",K38,0) -> 0
... A54: =ROW(A54)-7 -> 47 | B54: 2.01.04.08 | C54: VISA GUAYAQUIL | D54: =+#REF! -> #REF! | E54: 525 | F54: =IFERROR(VLOOKUP($E54,Casilleros!$A$4:$I$830,4,FALSE),"") -> PASIVOS CORRIENTES | G54: =IFERROR(VLOOKUP($E54,Casilleros!$A$4:$I$830,9,FALSE),"") -> OBLIGACIONES CON INSTITUCIONES FINANCIERAS - CORRIENTES_NO RELACIONADAS_Locales_ | H54: =IFERROR(VLOOKUP($E54,Casilleros!$A$4:$J$830,10,FALSE),"") -> Cbligaciones con instituciones financieras - corrientes | I54: =SUMIF(#REF!,$B54,#REF!) -> #REF! | J54: =SUMIF(#REF!,$B54,#REF!) -> #REF! | K54: =+D54+SUM(I54:J54) -> #REF! | L54: =IF(E54="",K54,0) -> 0
A55: =ROW(A55)-7 -> 48 | B55: 2.01.03.02 | C55: PRESTAMOS BANCARIOS | E55: 523 | F55: =IFERROR(VLOOKUP($E55,Casilleros!$A$4:$I$830,4,FALSE),"") -> PASIVOS CORRIENTES | G55: =IFERROR(VLOOKUP($E55,Casilleros!$A$4:$I$830,9,FALSE),"") -> OBLIGACIONES CON INSTITUCIONES FINANCIERAS - CORRIENTES_RELACIONADAS_Locales_ | H55: =IFERROR(VLOOKUP($E55,Casilleros!$A$4:$J$830,10,FALSE),"") -> Cbligaciones con instituciones financieras - corrientes | I55: =SUMIF(#REF!,$B55,#REF!) -> #REF! | J55: =SUMIF(#REF!,$B55,#REF!) -> #REF! | K55: =+D55+SUM(I55:J55) -> #REF! | L55: =IF(E55="",K55,0) -> 0
...

Sheet F101
A1: =RAZÓN_SOCIAL -> #REF!
A2: Formulario Renta Sociedades
A3: =Ejercicio_fiscal -> #REF!
A5: FORMULARIO RENTA SOCIEDADES
S6: =+N6 -> 0 | T6: =IF(A6<>"",A6,T5) -> 0 | U6: =IF(T5<>T6,"",(IF(B6<>"",B6,U5))) -> 0 | V6: =IF(U5<>U6,"",(IF(C6<>"",C6,V5))) -> 0 | W6: =IF(V5<>V6,"",(IF(D6<>"",D6,W5))) -> 0 | X6: =IF(W5<>W6,"",(IF(E6<>"",E6,X5))) -> 0 | Y6: =IF(X5<>X6,"",(IF(F6<>"",F6,Y5))) -> 0 | Z6: =IF(Y5<>Y6,"",(IF(G6<>"",G6,Z5))) -> 0 | AA6: =IF(X6<>"",CONCATENATE(W6,"_",X6,"_",Y6,"_",Z6,""),CONCATENATE(U6,"_",V6, "_",W6,"")) -> 0_0_0_0
A7: OPERACIONES CON PARTES RELACIONADAS LOCALES Y/O DEL EXTERIOR | S7: =+N7 -> 0 | T7: =IF(A7<>"",A7,T6) -> OPERACIONES CON PARTES RELACIONADAS LOCALES Y/O DEL EXTERIOR | U7: =IF(T6<>T7,"",(IF(B7<>"",B7,U6))) | V7: =IF(U6<>U7,"",(IF(C7<>"",C7,V6))) | W7: =IF(V6<>V7,"",(IF(D7<>"",D7,W6))) | X7: =IF(W6<>W7,"",(IF(E7<>"",E7,X6))) | Y7: =IF(X6<>X7,"",(IF(F7<>"",F7,Y6))) | Z7: =IF(Y6<>Y7,"",(IF(G7<>"",G7,Z6))) | AA7: =IF(X7<>"",CONCATENATE(W7,"_",X7,"_",Y7,"_",Z7,""),CONCATENATE(U7,"_",V7, "_",W7,"")) -> __
B8: CON PARTES RELACIONADAS LOCALES | S8: =+N8 -> 0 | T8: =IF(A8<>"",A8,T7) -> OPERACIONES CON PARTES RELACIONADAS LOCALES Y/O DEL EXTERIOR | U8: =IF(T7<>T8,"",(IF(B8<>"",B8,U7))) -> CON PARTES RELACIONADAS LOCALES | V8: =IF(U7<>U8,"",(IF(C8<>"",C8,V7))) | W8: =IF(V7<>V8,"",(IF(D8<>"",D8,W7))) | X8: =IF(W7<>W8,"",(IF(E8<>"",E8,X7))) | Y8: =IF(X7<>X8,"",(IF(F8<>"",F8,Y7))) | Z8: =IF(Y7<>Y8,"",(IF(G8<>"",G8,Z7))) | AA8: =IF(X8<>"",CONCATENATE(W8,"_",X8,"_",Y8,"_",Z8,""),CONCATENATE(U8,"_",V8, "_",W8,"")) -> CON PARTES RELACIONADAS LOCALES__
C9: Operaciones de activo | N9: 003 | O9: =VLOOKUP(N9,Casilleros!$A$4:$Q$830,17,FALSE) -> #REF! | S9: =+N9 -> 003 | T9: =IF(A9<>"",A9,T8) -> OPERACIONES CON PARTES RELACIONADAS LOCALES Y/O DEL EXTERIOR | U9: =IF(T8<>T9,"",(IF(B9<>"",B9,U8))) -> CON PARTES RELACIONADAS LOCALES | V9: =IF(U8<>U9,"",(IF(C9<>"",C9,V8))) -> Operaciones de activo | W9: =IF(V8<>V9,"",(IF(D9<>"",D9,W8))) | X9: =IF(W8<>W9,"",(IF(E9<>"",E9,X8))) | Y9: =IF(X8<>X9,"",(IF(F9<>"",F9,Y8))) | Z9: =IF(Y8<>Y9,"",(IF(G9<>"",G9,Z8))) | AA9: =IF(X9<>"",CONCATENATE(W9,"_",X9,"_",Y9,"_",Z9,""),CONCATENATE(U9,"_",V9, "_",W9,"")) -> CON PARTES RELACIONADAS LOCALES_Operaciones de activo_
C10: Operaciones de pasivo | N10: 004 | O10: =VLOOKUP(N10,Casilleros!$A$4:$Q$830,17,FALSE) -> #REF! | S10: =+N10 -> 004 | T10: =IF(A10<>"",A10,T9) -> OPERACIONES CON PARTES RELACIONADAS LOCALES Y/O DEL EXTERIOR | U10: =IF(T9<>T10,"",(IF(B10<>"",B10,U9))) -> CON PARTES RELACIONADAS LOCALES | V10: =IF(U9<>U10,"",(IF(C10<>"",C10,V9))) -> Operaciones de pasivo | W10: =IF(V9<>V10,"",(IF(D10<>"",D10,W9))) | X10: =IF(W9<>W10,"",(IF(E10<>"",E10,X9))) | Y10: =IF(X9<>X10,"",(IF(F10<>"",F10,Y9))) | Z10: =IF(Y9<>Y10,"",(IF(G10<>"",G10,Z9))) | AA10: =IF(X10<>"",CONCATENATE(W10,"_",X10,"_",Y10,"_",Z10,""),CONCATENATE(U10,"_",V10, "_",W10,"")) -> CON PARTES RELACIONADAS LOCALES_Operaciones de pasivo_
C11: Operaciones de ingreso | N11: 005 | O11: =VLOOKUP(N11,Casilleros!$A$4:$Q$830,17,FALSE) -> #REF! | S11: =+N11 -> 005 | T11: =IF(A11<>"",A11,T10) -> OPERACIONES CON PARTES RELACIONADAS LOCALES Y/O DEL EXTERIOR | U11: =IF(T10<>T11,"",(IF(B11<>"",B11,U10))) -> CON PARTES RELACIONADAS LOCALES | V11: =IF(U10<>U11,"",(IF(C11<>"",C11,V10))) -> Operaciones de ingreso | W11: =IF(V10<>V11,"",(IF(D11<>"",D11,W10))) | X11: =IF(W10<>W11,"",(IF(E11<>"",E11,X10))) | Y11: =IF(X10<>X11,"",(IF(F11<>"",F11,Y10))) | Z11: =IF(Y10<>Y11,"",(IF(G11<>"",G11,Z10))) | AA11: =IF(X11<>"",CONCATENATE(W11,"_",X11,"_",Y11,"_",Z11,""),CONCATENATE(U11,"_",V11, "_",W11,"")) -> CON PARTES RELACIONADAS LOCALES_Operaciones de ingreso_
C12: Operaciones de egreso | N12: 006 | O12: =VLOOKUP(N12,Casilleros!$A$4:$Q$830,17,FALSE) -> #REF! | S12: =+N12 -> 006 | T12: =IF(A12<>"",A12,T11) -> OPERACIONES CON PARTES RELACIONADAS LOCALES Y/O DEL EXTERIOR | U12: =IF(T11<>T12,"",(IF(B12<>"",B12,U11))) -> CON PARTES RELACIONADAS LOCALES | V12: =IF(U11<>U12,"",(IF(C12<>"",C12,V11))) -> Operaciones de egreso | W12: =IF(V11<>V12,"",(IF(D12<>"",D12,W11))) | X12: =IF(W11<>W12,"",(IF(E12<>"",E12,X11))) | Y12: =IF(X11<>X12,"",(IF(F12<>"",F12,Y11))) | Z12: =IF(Y11<>Y12,"",(IF(G12<>"",G12,Z11))) | AA12: =IF(X12<>"",CONCATENATE(W12,"_",X12,"_",Y12,"_",Z12,""),CONCATENATE(U12,"_",V12, "_",W12,"")) -> CON PARTES RELACIONADAS LOCALES_Operaciones de egreso_
C13: Operaciones de regalías, servicios técnicos, administrativos, de consultoría y similares | N13: 007 | O13: =VLOOKUP(N13,Casilleros!$A$4:$Q$830,17,FALSE) -> #REF! | S13: =+N13 -> 007 | T13: =IF(A13<>"",A13,T12) -> OPERACIONES CON PARTES RELACIONADAS LOCALES Y/O DEL EXTERIOR | U13: =IF(T12<>T13,"",(IF(B13<>"",B13,U12))) -> CON PARTES RELACIONADAS LOCALES | V13: =IF(U12<>U13,"",(IF(C13<>"",C13,V12))) -> Operaciones de regalías, servicios técnicos, administrativos, de consultoría y similares | W13: =IF(V12<>V13,"",(IF(D13<>"",D13,W12))) | X13: =IF(W12<>W13,"",(IF(E13<>"",E13,X12))) | Y13: =IF(X12<>X13,"",(IF(F13<>"",F13,Y12))) | Z13: =IF(Y12<>Y13,"",(IF(G13<>"",G13,Z12))) | AA13: =IF(X13<>"",CONCATENATE(W13,"_",X13,"_",Y13,"_",Z13,""),CONCATENATE(U13,"_",V13, "_",W13,"")) -> CON PARTES RELACIONADAS LOCALES_Operaciones de regalías, servicios técnicos, administrativos, de consultoría y similares_
B14: CON PARTES RELACIONADAS EN PARAÍSOS FISCALES, JURISDICCIONES DE MENOR IMPOSICIÓN Y RÉGIMENES FISCALES PREFERENTES | S14: =+N14 -> 0 | T14: =IF(A14<>"",A14,T13) -> OPERACIONES CON PARTES RELACIONADAS LOCALES Y/O DEL EXTERIOR | U14: =IF(T13<>T14,"",(IF(B14<>"",B14,U13))) -> CON PARTES RELACIONADAS EN PARAÍSOS FISCALES, JURISDICCIONES DE MENOR IMPOSICIÓN Y RÉGIMENES FISCALES PREFERENTES | V14: =IF(U13<>U14,"",(IF(C14<>"",C14,V13))) | W14: =IF(V13<>V14,"",(IF(D14<>"",D14,W13))) | X14: =IF(W13<>W14,"",(IF(E14<>"",E14,X13))) | Y14: =IF(X13<>X14,"",(IF(F14<>"",F14,Y13))) | Z14: =IF(Y13<>Y14,"",(IF(G14<>"",G14,Z13))) | AA14: =IF(X14<>"",CONCATENATE(W14,"_",X14,"_",Y14,"_",Z14,""),CONCATENATE(U14,"_",V14, "_",W14,"")) -> CON PARTES RELACIONADAS EN PARAÍSOS FISCALES, JURISDICCIONES DE MENOR IMPOSICIÓN Y RÉGIMENES FISCALES PREFERENTES__
C15: Operaciones de activo | N15: 008 | O15: =VLOOKUP(N15,Casilleros!$A$4:$Q$830,17,FALSE) -> #REF! | S15: =+N15 -> 008 | T15: =IF(A15<>"",A15,T14) -> OPERACIONES CON PARTES RELACIONADAS LOCALES Y/O DEL EXTERIOR | U15: =IF(T14<>T15,"",(IF(B15<>"",B15,U14))) -> CON PARTES RELACIONADAS EN PARAÍSOS FISCALES, JURISDICCIONES DE MENOR IMPOSICIÓN Y RÉGIMENES FISCALES PREFERENTES | V15: =IF(U14<>U15,"",(IF(C15<>"",C15,V14))) -> Operaciones de activo | W15: =IF(V14<>V15,"",(IF(D15<>"",D15,W14))) | X15: =IF(W14<>W15,"",(IF(E15<>"",E15,X14))) | Y15: =IF(X14<>X15,"",(IF(F15<>"",F15,Y14))) | Z15: =IF(Y14<>Y15,"",(IF(G15<>"",G15,Z14))) | AA15: =IF(X15<>"",CONCATENATE(W15,"_",X15,"_",Y15,"_",Z15,""),CONCATENATE(U15,"_",V15, "_",W15,"")) -> CON PARTES RELACIONADAS EN PARAÍSOS FISCALES, JURISDICCIONES DE MENOR IMPOSICIÓN Y RÉGIMENES FISCALES PREFERENTES_Operaciones de activo_
C16: Operaciones de pasivo | N16: 009 | O16: =VLOOKUP(N16,Casilleros!$A$4:$Q$830,17,FALSE) -> #REF! | S16: =+N16 -> 009 | T16: =IF(A16<>"",A16,T15) -> OPERACIONES CON PARTES RELACIONADAS LOCALES Y/O DEL EXTERIOR | U16: =IF(T15<>T16,"",(IF(B16<>"",B16,U15))) -> CON PARTES RELACIONADAS EN PARAÍSOS FISCALES, JURISDICCIONES DE MENOR IMPOSICIÓN Y RÉGIMENES FISCALES PREFERENTES | V16: =IF(U15<>U16,"",(IF(C16<>"",C16,V15))) -> Operaciones de pasivo | W16: =IF(V15<>V16,"",(IF(D16<>"",D16,W15))) | X16: =IF(W15<>W16,"",(IF(E16<>"",E16,X15))) | Y16: =IF(X15<>X16,"",(IF(F16<>"",F16,Y15))) | Z16: =IF(Y15<>Y16,"",(IF(G16<>"",G16,Z15))) | AA16: =IF(X16<>"",CONCATENATE(W16,"_",X16,"_",Y16,"_",Z16,""),CONCATENATE(U16,"_",V16, "_",W16,"")) -> CON PARTES RELACIONADAS EN PARAÍSOS FISCALES, JURISDICCIONES DE MENOR IMPOSICIÓN Y RÉGIMENES FISCALES PREFERENTES_Operaciones de pasivo_
C17: Operaciones de ingreso | N17: 010 | O17: =VLOOKUP(N17,Casilleros!$A$4:$Q$830,17,FALSE) -> #REF! | S17: =+N17 -> 010 | T17: =IF(A17<>"",A17,T16) -> OPERACIONES CON PARTES RELACIONADAS LOCALES Y/O DEL EXTERIOR | U17: =IF(T16<>T17,"",(IF(B17<>"",B17,U16))) -> CON PARTES RELACIONADAS EN PARAÍSOS FISCALES, JURISDICCIONES DE MENOR IMPOSICIÓN Y RÉGIMENES FISCALES PREFERENTES | V17: =IF(U16<>U17,"",(IF(C17<>"",C17,V16))) -> Operaciones de ingreso | W17: =IF(V16<>V17,"",(IF(D17<>"",D17,W16))) | X17: =IF(W16<>W17,"",(IF(E17<>"",E17,X16))) | Y17: =IF(X16<>X17,"",(IF(F17<>"",F17,Y16))) | Z17: =IF(Y16<>Y17,"",(IF(G17<>"",G17,Z16))) | AA17: =IF(X17<>"",CONCATENATE(W17,"_",X17,"_",Y17,"_",Z17,""),CONCATENATE(U17,"_",V17, "_",W17,"")) -> CON PARTES RELACIONADAS EN PARAÍSOS FISCALES, JURISDICCIONES DE MENOR IMPOSICIÓN Y RÉGIMENES FISCALES PREFERENTES_Operaciones de ingreso_
C18: Operaciones de egreso | N18: 011 | O18: =VLOOKUP(N18,Casilleros!$A$4:$Q$830,17,FALSE) -> #REF! | S18: =+N18 -> 011 | T18: =IF(A18<>"",A18,T17) -> OPERACIONES CON PARTES RELACIONADAS LOCALES Y/O DEL EXTERIOR | U18: =IF(T17<>T18,"",(IF(B18<>"",B18,U17))) -> CON PARTES RELACIONADAS EN PARAÍSOS FISCALES, JURISDICCIONES DE MENOR IMPOSICIÓN Y RÉGIMENES FISCALES PREFERENTES | V18: =IF(U17<>U18,"",(IF(C18<>"",C18,V17))) -> Operaciones de egreso | W18: =IF(V17<>V18,"",(IF(D18<>"",D18,W17))) | X18: =IF(W17<>W18,"",(IF(E18<>"",E18,X17))) | Y18: =IF(X17<>X18,"",(IF(F18<>"",F18,Y17))) | Z18: =IF(Y17<>Y18,"",(IF(G18<>"",G18,Z17))) | AA18: =IF(X18<>"",CONCATENATE(W18,"_",X18,"_",Y18,"_",Z18,""),CONCATENATE(U18,"_",V18, "_",W18,"")) -> CON PARTES RELACIONADAS EN PARAÍSOS FISCALES, JURISDICCIONES DE MENOR IMPOSICIÓN Y RÉGIMENES FISCALES PREFERENTES_Operaciones de egreso_
C19: Operaciones de regalías, servicios técnicos, administrativos, de consultoría y similares | N19: 012 | O19: =VLOOKUP(N19,Casilleros!$A$4:$Q$830,17,FALSE) -> #REF! | S19: =+N19 -> 012 | T19: =IF(A19<>"",A19,T18) -> OPERACIONES CON PARTES RELACIONADAS LOCALES Y/O DEL EXTERIOR | U19: =IF(T18<>T19,"",(IF(B19<>"",B19,U18))) -> CON PARTES RELACIONADAS EN PARAÍSOS FISCALES, JURISDICCIONES DE MENOR IMPOSICIÓN Y RÉGIMENES FISCALES PREFERENTES | V19: =IF(U18<>U19,"",(IF(C19<>"",C19,V18))) -> Operaciones de regalías, servicios técnicos, administrativos, de consultoría y similares | W19: =IF(V18<>V19,"",(IF(D19<>"",D19,W18))) | X19: =IF(W18<>W19,"",(IF(E19<>"",E19,X18))) | Y19: =IF(X18<>X19,"",(IF(F19<>"",F19,Y18))) | Z19: =IF(Y18<>Y19,"",(IF(G19<>"",G19,Z18))) | AA19: =IF(X19<>"",CONCATENATE(W19,"_",X19,"_",Y19,"_",Z19,""),CONCATENATE(U19,"_",V19, "_",W19,"")) -> CON PARTES RELACIONADAS EN PARAÍSOS FISCALES, JURISDICCIONES DE MENOR IMPOSICIÓN Y RÉGIMENES FISCALES PREFERENTES_Operaciones de regalías, servicios técnicos, administrativos, de consultoría y similares_
B20: CON PARTES RELACIONADAS EN OTRAS JURISDICCIONES O RÉGIMENES DEL EXTERIOR | S20: =+N20 -> 0 | T20: =IF(A20<>"",A20,T19) -> OPERACIONES CON PARTES RELACIONADAS LOCALES Y/O DEL EXTERIOR | U20: =IF(T19<>T20,"",(IF(B20<>"",B20,U19))) -> CON PARTES RELACIONADAS EN OTRAS JURISDICCIONES O RÉGIMENES DEL EXTERIOR | V20: =IF(U19<>U20,"",(IF(C20<>"",C20,V19))) | W20: =IF(V19<>V20,"",(IF(D20<>"",D20,W19))) | X20: =IF(W19<>W20,"",(IF(E20<>"",E20,X19))) | Y20: =IF(X19<>X20,"",(IF(F20<>"",F20,Y19))) | Z20: =IF(Y19<>Y20,"",(IF(G20<>"",G20,Z19))) | AA20: =IF(X20<>"",CONCATENATE(W20,"_",X20,"_",Y20,"_",Z20,""),CONCATENATE(U20,"_",V20, "_",W20,"")) -> CON PARTES RELACIONADAS EN OTRAS JURISDICCIONES O RÉGIMENES DEL EXTERIOR__
C21: Operaciones de activo | N21: 013 | O21: =VLOOKUP(N21,Casilleros!$A$4:$Q$830,17,FALSE) -> #REF! | S21: =+N21 -> 013 | T21: =IF(A21<>"",A21,T20) -> OPERACIONES CON PARTES RELACIONADAS LOCALES Y/O DEL EXTERIOR | U21: =IF(T20<>T21,"",(IF(B21<>"",B21,U20))) -> CON PARTES RELACIONADAS EN OTRAS JURISDICCIONES O RÉGIMENES DEL EXTERIOR | V21: =IF(U20<>U21,"",(IF(C21<>"",C21,V20))) -> Operaciones de activo | W21: =IF(V20<>V21,"",(IF(D21<>"",D21,W20))) | X21: =IF(W20<>W21,"",(IF(E21<>"",E21,X20))) | Y21: =IF(X20<>X21,"",(IF(F21<>"",F21,Y20))) | Z21: =IF(Y20<>Y21,"",(IF(G21<>"",G21,Z20))) | AA21: =IF(X21<>"",CONCATENATE(W21,"_",X21,"_",Y21,"_",Z21,""),CONCATENATE(U21,"_",V21, "_",W21,"")) -> CON PARTES RELACIONADAS EN OTRAS JURISDICCIONES O RÉGIMENES DEL EXTERIOR_Operaciones de activo_
C22: Operaciones de pasivo | N22: 014 | O22: =VLOOKUP(N22,Casilleros!$A$4:$Q$830,17,FALSE) -> #REF! | S22: =+N22 -> 014 | T22: =IF(A22<>"",A22,T21) -> OPERACIONES CON PARTES RELACIONADAS LOCALES Y/O DEL EXTERIOR | U22: =IF(T21<>T22,"",(IF(B22<>"",B22,U21))) -> CON PARTES RELACIONADAS EN OTRAS JURISDICCIONES O RÉGIMENES DEL EXTERIOR | V22: =IF(U21<>U22,"",(IF(C22<>"",C22,V21))) -> Operaciones de pasivo | W22: =IF(V21<>V22,"",(IF(D22<>"",D22,W21))) | X22: =IF(W21<>W22,"",(IF(E22<>"",E22,X21))) | Y22: =IF(X21<>X22,"",(IF(F22<>"",F22,Y21))) | Z22: =IF(Y21<>Y22,"",(IF(G22<>"",G22,Z21))) | AA22: =IF(X22<>"",CONCATENATE(W22,"_",X22,"_",Y22,"_",Z22,""),CONCATENATE(U22,"_",V22, "_",W22,"")) -> CON PARTES RELACIONADAS EN OTRAS JURISDICCIONES O RÉGIMENES DEL EXTERIOR_Operaciones de pasivo_
C23: Operaciones de ingreso | N23: 015 | O23: =VLOOKUP(N23,Casilleros!$A$4:$Q$830,17,FALSE) -> #REF! | S23: =+N23 -> 015 | T23: =IF(A23<>"",A23,T22) -> OPERACIONES CON PARTES RELACIONADAS LOCALES Y/O DEL EXTERIOR | U23: =IF(T22<>T23,"",(IF(B23<>"",B23,U22))) -> CON PARTES RELACIONADAS EN OTRAS JURISDICCIONES O RÉGIMENES DEL EXTERIOR | V23: =IF(U22<>U23,"",(IF(C23<>"",C23,V22))) -> Operaciones de ingreso | W23: =IF(V22<>V23,"",(IF(D23<>"",D23,W22))) | X23: =IF(W22<>W23,"",(IF(E23<>"",E23,X22))) | Y23: =IF(X22<>X23,"",(IF(F23<>"",F23,Y22))) | Z23: =IF(Y22<>Y23,"",(IF(G23<>"",G23,Z22))) | AA23: =IF(X23<>"",CONCATENATE(W23,"_",X23,"_",Y23,"_",Z23,""),CONCATENATE(U23,"_",V23, "_",W23,"")) -> CON PARTES RELACIONADAS EN OTRAS JURISDICCIONES O RÉGIMENES DEL EXTERIOR_Operaciones de ingreso_
C24: Operaciones de egreso | N24: 016 | O24: =VLOOKUP(N24,Casilleros!$A$4:$Q$830,17,FALSE) -> #REF! | S24: =+N24 -> 016 | T24: =IF(A24<>"",A24,T23) -> OPERACIONES CON PARTES RELACIONADAS LOCALES Y/O DEL EXTERIOR | U24: =IF(T23<>T24,"",(IF(B24<>"",B24,U23))) -> CON PARTES RELACIONADAS EN OTRAS JURISDICCIONES O RÉGIMENES DEL EXTERIOR | V24: =IF(U23<>U24,"",(IF(C24<>"",C24,V23))) -> Operaciones de egreso | W24: =IF(V23<>V24,"",(IF(D24<>"",D24,W23))) | X24: =IF(W23<>W24,"",(IF(E24<>"",E24,X23))) | Y24: =IF(X23<>X24,"",(IF(F24<>"",F24,Y23))) | Z24: =IF(Y23<>Y24,"",(IF(G24<>"",G24,Z23))) | AA24: =IF(X24<>"",CONCATENATE(W24,"_",X24,"_",Y24,"_",Z24,""),CONCATENATE(U24,"_",V24, "_",W24,"")) -> CON PARTES RELACIONADAS EN OTRAS JURISDICCIONES O RÉGIMENES DEL EXTERIOR_Operaciones de egreso_
C25: Operaciones de regalías, servicios técnicos, administrativos, de consultoría y similares | N25: 017 | O25: =VLOOKUP(N25,Casilleros!$A$4:$Q$830,17,FALSE) -> #REF! | S25: =+N25 -> 017 | T25: =IF(A25<>"",A25,T24) -> OPERACIONES CON PARTES RELACIONADAS LOCALES Y/O DEL EXTERIOR | U25: =IF(T24<>T25,"",(IF(B25<>"",B25,U24))) -> CON PARTES RELACIONADAS EN OTRAS JURISDICCIONES O RÉGIMENES DEL EXTERIOR | V25: =IF(U24<>U25,"",(IF(C25<>"",C25,V24))) -> Operaciones de regalías, servicios técnicos, administrativos, de consultoría y similares | W25: =IF(V24<>V25,"",(IF(D25<>"",D25,W24))) | X25: =IF(W24<>W25,"",(IF(E25<>"",E25,X24))) | Y25: =IF(X24<>X25,"",(IF(F25<>"",F25,Y24))) | Z25: =IF(Y24<>Y25,"",(IF(G25<>"",G25,Z24))) | AA25: =IF(X25<>"",CONCATENATE(W25,"_",X25,"_",Y25,"_",Z25,""),CONCATENATE(U25,"_",V25, "_",W25,"")) -> CON PARTES RELACIONADAS EN OTRAS JURISDICCIONES O RÉGIMENES DEL EXTERIOR_Operaciones de regalías, servicios técnicos, administrativos, de consultoría y similares_
B26: TOTAL OPERACIONES CON PARTES RELACIONADAS | N26: 029 | O26: =SUM(O9:O13)+SUM(O15:O19)+SUM(O21:O25) -> #REF! | S26: =+N26 -> 029 | T26: =IF(A26<>"",A26,T25) -> OPERACIONES CON PARTES RELACIONADAS LOCALES Y/O DEL EXTERIOR | U26: =IF(T25<>T26,"",(IF(B26<>"",B26,U25))) -> TOTAL OPERACIONES CON PARTES RELACIONADAS | V26: =IF(U25<>U26,"",(IF(C26<>"",C26,V25))) | W26: =IF(V25<>V26,"",(IF(D26<>"",D26,W25))) | X26: =IF(W25<>W26,"",(IF(E26<>"",E26,X25))) | Y26: =IF(X25<>X26,"",(IF(F26<>"",F26,Y25))) | Z26: =IF(Y25<>Y26,"",(IF(G26<>"",G26,Z25))) | AA26: =IF(X26<>"",CONCATENATE(W26,"_",X26,"_",Y26,"_",Z26,""),CONCATENATE(U26,"_",V26, "_",W26,"")) -> TOTAL OPERACIONES CON PARTES RELACIONADAS__
B27: ¿Sujeto pasivo exento de aplicación del régimen de precios de transferencia? | N27: 030 | S27: =+N27 -> 030 | T27: =IF(A27<>"",A27,T26) -> OPERACIONES CON PARTES RELACIONADAS LOCALES Y/O DEL EXTERIOR | U27: =IF(T26<>T27,"",(IF(B27<>"",B27,U26))) -> ¿Sujeto pasivo exento de aplicación del régimen de precios de transferencia? | V27: =IF(U26<>U27,"",(IF(C27<>"",C27,V26))) | W27: =IF(V26<>V27,"",(IF(D27<>"",D27,W26))) | X27: =IF(W26<>W27,"",(IF(E27<>"",E27,X26))) | Y27: =IF(X26<>X27,"",(IF(F27<>"",F27,Y26))) | Z27: =IF(Y26<>Y27,"",(IF(G27<>"",G27,Z26))) | AA27: =IF(X27<>"",CONCATENATE(W27,"_",X27,"_",Y27,"_",Z27,""),CONCATENATE(U27,"_",V27, "_",W27,"")) -> ¿Sujeto pasivo exento de aplicación del régimen de precios de transferencia?__
A28: ESTADO DE SITUACIÓN FINANCIERA | S28: =+N28 -> 0 | T28: =IF(A28<>"",A28,T27) -> ESTADO DE SITUACIÓN FINANCIERA | U28: =IF(T27<>T28,"",(IF(B28<>"",B28,U27))) | V28: =IF(U27<>U28,"",(IF(C28<>"",C28,V27))) | W28: =IF(V27<>V28,"",(IF(D28<>"",D28,W27))) | X28: =IF(W27<>W28,"",(IF(E28<>"",E28,X27))) | Y28: =IF(X27<>X28,"",(IF(F28<>"",F28,Y27))) | Z28: =IF(Y27<>Y28,"",(IF(G28<>"",G28,Z27))) | AA28: =IF(X28<>"",CONCATENATE(W28,"_",X28,"_",Y28,"_",Z28,""),CONCATENATE(U28,"_",V28, "_",W28,"")) -> __
B29: ACTIVO | S29: =+N29 -> 0 | T29: =IF(A29<>"",A29,T28) -> ESTADO DE SITUACIÓN FINANCIERA | U29: =IF(T28<>T29,"",(IF(B29<>"",B29,U28))) -> ACTIVO | V29: =IF(U28<>U29,"",(IF(C29<>"",C29,V28))) | W29: =IF(V28<>V29,"",(IF(D29<>"",D29,W28))) | X29: =IF(W28<>W29,"",(IF(E29<>"",E29,X28))) | Y29: =IF(X28<>X29,"",(IF(F29<>"",F29,Y28))) | Z29: =IF(Y28<>Y29,"",(IF(G29<>"",G29,Z28))) | AA29: =IF(X29<>"",CONCATENATE(W29,"_",X29,"_",Y29,"_",Z29,""),CONCATENATE(U29,"_",V29, "_",W29,"")) -> ACTIVO__
C30: ACTIVOS CORRIENTES | S30: =+N30 -> 0 | T30: =IF(A30<>"",A30,T29) -> ESTADO DE SITUACIÓN FINANCIERA | U30: =IF(T29<>T30,"",(IF(B30<>"",B30,U29))) -> ACTIVO | V30: =IF(U29<>U30,"",(IF(C30<>"",C30,V29))) -> ACTIVOS CORRIENTES | W30: =IF(V29<>V30,"",(IF(D30<>"",D30,W29))) | X30: =IF(W29<>W30,"",(IF(E30<>"",E30,X29))) | Y30: =IF(X29<>X30,"",(IF(F30<>"",F30,Y29))) | Z30: =IF(Y29<>Y30,"",(IF(G30<>"",G30,Z29))) | AA30: =IF(X30<>"",CONCATENATE(W30,"_",X30,"_",Y30,"_",Z30,""),CONCATENATE(U30,"_",V30, "_",W30,"")) -> ACTIVO_ACTIVOS CORRIENTES_
D31: Efectivo y equivalentes al efectivo | N31: 311 | O31: =VLOOKUP(N31,Casilleros!$A$4:$Q$830,17,FALSE) -> #REF! | S31: =+N31 -> 311 | T31: =IF(A31<>"",A31,T30) -> ESTADO DE SITUACIÓN FINANCIERA | U31: =IF(T30<>T31,"",(IF(B31<>"",B31,U30))) -> ACTIVO | V31: =IF(U30<>U31,"",(IF(C31<>"",C31,V30))) -> ACTIVOS CORRIENTES | W31: =IF(V30<>V31,"",(IF(D31<>"",D31,W30))) -> Efectivo y equivalentes al efectivo | X31: =IF(W30<>W31,"",(IF(E31<>"",E31,X30))) | Y31: =IF(X30<>X31,"",(IF(F31<>"",F31,Y30))) | Z31: =IF(Y30<>Y31,"",(IF(G31<>"",G31,Z30))) | AA31: =IF(X31<>"",CONCATENATE(W31,"_",X31,"_",Y31,"_",Z31),W31) -> Efectivo y equivalentes al efectivo
D32: CUENTAS Y DOCUMENTOS POR COBRAR CORRIENTES | S32: =+N32 -> 0 | T32: =IF(A32<>"",A32,T31) -> ESTADO DE SITUACIÓN FINANCIERA | U32: =IF(T31<>T32,"",(IF(B32<>"",B32,U31))) -> ACTIVO | V32: =IF(U31<>U32,"",(IF(C32<>"",C32,V31))) -> ACTIVOS CORRIENTES | W32: =IF(V31<>V32,"",(IF(D32<>"",D32,W31))) -> CUENTAS Y DOCUMENTOS POR COBRAR CORRIENTES | X32: =IF(W31<>W32,"",(IF(E32<>"",E32,X31))) | Y32: =IF(X31<>X32,"",(IF(F32<>"",F32,Y31))) | Z32: =IF(Y31<>Y32,"",(IF(G32<>"",G32,Z31))) | AA32: =IF(X32<>"",CONCATENATE(W32,"_",X32,"_",Y32,"_",Z32),W32) -> CUENTAS Y DOCUMENTOS POR COBRAR CORRIENTES
E33: CUENTAS Y DOCUMENTOS POR COBRAR COMERCIALES CORRIENTES | S33: =+N33 -> 0 | T33: =IF(A33<>"",A33,T32) -> ESTADO DE SITUACIÓN FINANCIERA | U33: =IF(T32<>T33,"",(IF(B33<>"",B33,U32))) -> ACTIVO | V33: =IF(U32<>U33,"",(IF(C33<>"",C33,V32))) -> ACTIVOS CORRIENTES | W33: =IF(V32<>V33,"",(IF(D33<>"",D33,W32))) -> CUENTAS Y DOCUMENTOS POR COBRAR CORRIENTES | X33: =IF(W32<>W33,"",(IF(E33<>"",E33,X32))) -> CUENTAS Y DOCUMENTOS POR COBRAR COMERCIALES CORRIENTES | Y33: =IF(X32<>X33,"",(IF(F33<>"",F33,Y32))) | Z33: =IF(Y32<>Y33,"",(IF(G33<>"",G33,Z32))) | AA33: =IF(X33<>"",CONCATENATE(W33,"_",X33,"_",Y33,"_",Z33),W33) -> CUENTAS Y DOCUMENTOS POR COBRAR CORRIENTES_CUENTAS Y DOCUMENTOS POR COBRAR COMERCIALES CORRIENTES__
F34: RELACIONADAS | S34: =+N34 -> 0 | T34: =IF(A34<>"",A34,T33) -> ESTADO DE SITUACIÓN FINANCIERA | U34: =IF(T33<>T34,"",(IF(B34<>"",B34,U33))) -> ACTIVO | V34: =IF(U33<>U34,"",(IF(C34<>"",C34,V33))) -> ACTIVOS CORRIENTES | W34: =IF(V33<>V34,"",(IF(D34<>"",D34,W33))) -> CUENTAS Y DOCUMENTOS POR COBRAR CORRIENTES | X34: =IF(W33<>W34,"",(IF(E34<>"",E34,X33))) -> CUENTAS Y DOCUMENTOS POR COBRAR COMERCIALES CORRIENTES | Y34: =IF(X33<>X34,"",(IF(F34<>"",F34,Y33))) -> RELACIONADAS | Z34: =IF(Y33<>Y34,"",(IF(G34<>"",G34,Z33))) | AA34: =IF(X34<>"",CONCATENATE(W34,"_",X34,"_",Y34,"_",Z34),W34) -> CUENTAS Y DOCUMENTOS POR COBRAR CORRIENTES_CUENTAS Y DOCUMENTOS POR COBRAR COMERCIALES CORRIENTES_RELACIONADAS_
G35: Locales | N35: 312 | O35: =VLOOKUP(N35,Casilleros!$A$4:$Q$830,17,FALSE) -> #REF! | S35: =+N35 -> 312 | T35: =IF(A35<>"",A35,T34) -> ESTADO DE SITUACIÓN FINANCIERA | U35: =IF(T34<>T35,"",(IF(B35<>"",B35,U34))) -> ACTIVO | V35: =IF(U34<>U35,"",(IF(C35<>"",C35,V34))) -> ACTIVOS CORRIENTES | W35: =IF(V34<>V35,"",(IF(D35<>"",D35,W34))) -> CUENTAS Y DOCUMENTOS POR COBRAR CORRIENTES | X35: =IF(W34<>W35,"",(IF(E35<>"",E35,X34))) -> CUENTAS Y DOCUMENTOS POR COBRAR COMERCIALES CORRIENTES | Y35: =IF(X34<>X35,"",(IF(F35<>"",F35,Y34))) -> RELACIONADAS | Z35: =IF(Y34<>Y35,"",(IF(G35<>"",G35,Z34))) -> Locales | AA35: =IF(X35<>"",CONCATENATE(W35,"_",X35,"_",Y35,"_",Z35),W35) -> CUENTAS Y DOCUMENTOS POR COBRAR CORRIENTES_CUENTAS Y DOCUMENTOS POR COBRAR COMERCIALES CORRIENTES_RELACIONADAS_Locales
G36: Del exterior | N36: 313 | O36: =VLOOKUP(N36,Casilleros!$A$4:$Q$830,17,FALSE) -> #REF! | S36: =+N36 -> 313 | T36: =IF(A36<>"",A36,T35) -> ESTADO DE SITUACIÓN FINANCIERA | U36: =IF(T35<>T36,"",(IF(B36<>"",B36,U35))) -> ACTIVO | V36: =IF(U35<>U36,"",(IF(C36<>"",C36,V35))) -> ACTIVOS CORRIENTES | W36: =IF(V35<>V36,"",(IF(D36<>"",D36,W35))) -> CUENTAS Y DOCUMENTOS POR COBRAR CORRIENTES | X36: =IF(W35<>W36,"",(IF(E36<>"",E36,X35))) -> CUENTAS Y DOCUMENTOS POR COBRAR COMERCIALES CORRIENTES | Y36: =IF(X35<>X36,"",(IF(F36<>"",F36,Y35))) -> RELACIONADAS | Z36: =IF(Y35<>Y36,"",(IF(G36<>"",G36,Z35))) -> Del exterior | AA36: =IF(X36<>"",CONCATENATE(W36,"_",X36,"_",Y36,"_",Z36),W36) -> CUENTAS Y DOCUMENTOS POR COBRAR CORRIENTES_CUENTAS Y DOCUMENTOS POR COBRAR COMERCIALES CORRIENTES_RELACIONADAS_Del exterior
G37: (-) Deterioro acumulado del valor de cuentas y documentos por cobrar comerciales por incobrabilidad (provisiones para créditos incobrables) | N37: 314 | O37: =VLOOKUP(N37,Casilleros!$A$4:$Q$830,17,FALSE) -> #REF! | S37: =+N37 -> 314 | T37: =IF(A37<>"",A37,T36) -> ESTADO DE SITUACIÓN FINANCIERA | U37: =IF(T36<>T37,"",(IF(B37<>"",B37,U36))) -> ACTIVO | V37: =IF(U36<>U37,"",(IF(C37<>"",C37,V36))) -> ACTIVOS CORRIENTES | W37: =IF(V36<>V37,"",(IF(D37<>"",D37,W36))) -> CUENTAS Y DOCUMENTOS POR COBRAR CORRIENTES | X37: =IF(W36<>W37,"",(IF(E37<>"",E37,X36))) -> CUENTAS Y DOCUMENTOS POR COBRAR COMERCIALES CORRIENTES | Y37: =IF(X36<>X37,"",(IF(F37<>"",F37,Y36))) -> RELACIONADAS | Z37: =IF(Y36<>Y37,"",(IF(G37<>"",G37,Z36))) -> (-) Deterioro acumulado del valor de cuentas y documentos por cobrar comerciales por incobrabilidad (provisiones para créditos incobrables) | AA37: =IF(X37<>"",CONCATENATE(W37,"_",X37,"_",Y37,"_",Z37),W37) -> CUENTAS Y DOCUMENTOS POR COBRAR CORRIENTES_CUENTAS Y DOCUMENTOS POR COBRAR COMERCIALES CORRIENTES_RELACIONADAS_(-) Deterioro acumulado del valor de cuentas y documentos por cobrar comerciales por incobrabilidad (provisiones para créditos incobrables)
F38: NO RELACIONADAS | S38: =+N38 -> 0 | T38: =IF(A38<>"",A38,T37) -> ESTADO DE SITUACIÓN FINANCIERA | U38: =IF(T37<>T38,"",(IF(B38<>"",B38,U37))) -> ACTIVO | V38: =IF(U37<>U38,"",(IF(C38<>"",C38,V37))) -> ACTIVOS CORRIENTES | W38: =IF(V37<>V38,"",(IF(D38<>"",D38,W37))) -> CUENTAS Y DOCUMENTOS POR COBRAR CORRIENTES | X38: =IF(W37<>W38,"",(IF(E38<>"",E38,X37))) -> CUENTAS Y DOCUMENTOS POR COBRAR COMERCIALES CORRIENTES | Y38: =IF(X37<>X38,"",(IF(F38<>"",F38,Y37))) -> NO RELACIONADAS | Z38: =IF(Y37<>Y38,"",(IF(G38<>"",G38,Z37))) | AA38: =IF(X38<>"",CONCATENATE(W38,"_",X38,"_",Y38,"_",Z38),W38) -> CUENTAS Y DOCUMENTOS POR COBRAR CORRIENTES_CUENTAS Y DOCUMENTOS POR COBRAR COMERCIALES CORRIENTES_NO RELACIONADAS_
G39: Locales | N39: 315 | O39: =VLOOKUP(N39,Casilleros!$A$4:$Q$830,17,FALSE) -> #REF! | S39: =+N39 -> 315 | T39: =IF(A39<>"",A39,T38) -> ESTADO DE SITUACIÓN FINANCIERA | U39: =IF(T38<>T39,"",(IF(B39<>"",B39,U38))) -> ACTIVO | V39: =IF(U38<>U39,"",(IF(C39<>"",C39,V38))) -> ACTIVOS CORRIENTES | W39: =IF(V38<>V39,"",(IF(D39<>"",D39,W38))) -> CUENTAS Y DOCUMENTOS POR COBRAR CORRIENTES | X39: =IF(W38<>W39,"",(IF(E39<>"",E39,X38))) -> CUENTAS Y DOCUMENTOS POR COBRAR COMERCIALES CORRIENTES | Y39: =IF(X38<>X39,"",(IF(F39<>"",F39,Y38))) -> NO RELACIONADAS | Z39: =IF(Y38<>Y39,"",(IF(G39<>"",G39,Z38))) -> Locales | AA39: =IF(X39<>"",CONCATENATE(W39,"_",X39,"_",Y39,"_",Z39),W39) -> CUENTAS Y DOCUMENTOS POR COBRAR CORRIENTES_CUENTAS Y DOCUMENTOS POR COBRAR COMERCIALES CORRIENTES_NO RELACIONADAS_Locales
G40: Del exterior | N40: 316 | O40: =VLOOKUP(N40,Casilleros!$A$4:$Q$830,17,FALSE) -> #REF! | S40: =+N40 -> 316 | T40: =IF(A40<>"",A40,T39) -> ESTADO DE SITUACIÓN FINANCIERA | U40: =IF(T39<>T40,"",(IF(B40<>"",B40,U39))) -> ACTIVO | V40: =IF(U39<>U40,"",(IF(C40<>"",C40,V39))) -> ACTIVOS CORRIENTES | W40: =IF(V39<>V40,"",(IF(D40<>"",D40,W39))) -> CUENTAS Y DOCUMENTOS POR COBRAR CORRIENTES | X40: =IF(W39<>W40,"",(IF(E40<>"",E40,X39))) -> CUENTAS Y DOCUMENTOS POR COBRAR COMERCIALES CORRIENTES | Y40: =IF(X39<>X40,"",(IF(F40<>"",F40,Y39))) -> NO RELACIONADAS | Z40: =IF(Y39<>Y40,"",(IF(G40<>"",G40,Z39))) -> Del exterior | AA40: =IF(X40<>"",CONCATENATE(W40,"_",X40,"_",Y40,"_",Z40),W40) -> CUENTAS Y DOCUMENTOS POR COBRAR CORRIENTES_CUENTAS Y DOCUMENTOS POR COBRAR COMERCIALES CORRIENTES_NO RELACIONADAS_Del exterior
G41: (-) Deterioro acumulado del valor de cuentas y documentos por cobrar comerciales por incobrabilidad (provisiones para créditos incobrables) | N41: 317 | O41: =VLOOKUP(N41,Casilleros!$A$4:$Q$830,17,FALSE) -> #REF! | S41: =+N41 -> 317 | T41: =IF(A41<>"",A41,T40) -> ESTADO DE SITUACIÓN FINANCIERA | U41: =IF(T40<>T41,"",(IF(B41<>"",B41,U40))) -> ACTIVO | V41: =IF(U40<>U41,"",(IF(C41<>"",C41,V40))) -> ACTIVOS CORRIENTES | W41: =IF(V40<>V41,"",(IF(D41<>"",D41,W40))) -> CUENTAS Y DOCUMENTOS POR COBRAR CORRIENTES | X41: =IF(W40<>W41,"",(IF(E41<>"",E41,X40))) -> CUENTAS Y DOCUMENTOS POR COBRAR COMERCIALES CORRIENTES | Y41: =IF(X40<>X41,"",(IF(F41<>"",F41,Y40))) -> NO RELACIONADAS | Z41: =IF(Y40<>Y41,"",(IF(G41<>"",G41,Z40))) -> (-) Deterioro acumulado del valor de cuentas y documentos por cobrar comerciales por incobrabilidad (provisiones para créditos incobrables) | AA41: =IF(X41<>"",CONCATENATE(W41,"_",X41,"_",Y41,"_",Z41),W41) -> CUENTAS Y DOCUMENTOS POR COBRAR CORRIENTES_CUENTAS Y DOCUMENTOS POR COBRAR COMERCIALES CORRIENTES_NO RELACIONADAS_(-) Deterioro acumulado del valor de cuentas y documentos por cobrar comerciales por incobrabilidad (provisiones para créditos incobrables)
...

Sheet Tipo
B1: INGRESOS | D1: N. EMPLEADOS
A2: LIMITES | B2: Desde | C2: Hasta | D2: Desde | E2: Hasta
A3: MICROEMPRESA | B3: 0 | C3: 300000 | D3: 1 | E3: 9
A4: PEQUEÑA EMPRESA | B4: =+C3+1 -> 300001 | C4: 1000000 | D4: =+E3+1 -> 10 | E4: 49
A5: MEDIANA EMPRESA | B5: =+C4+1 -> 1000001 | C5: 5000000 | D5: =+E4+1 -> 50 | E5: 199

Sheet Casilleros
A1: =RAZÓN_SOCIAL -> #REF!
A2: Detalle de casilleros F101
A3: =Ejercicio_fiscal -> #REF!
A4: casillero | B4: Descripción1 | C4: Descripción2 | D4: Descripción3 | E4: Descripción4 | F4: Descripción5 | G4: Descripción6 | H4: Descripción7 | I4: Descripción_casillero | J4: Mapeo EF | K4: Monto BC | L4: Monto IE/No objeto | M4: Monto GND | N4: Deducciones adicionales | O4: Impuestos diferidos | P4: Casilleros Informativos | Q4: Total
A5: 003 | B5: OPERACIONES CON PARTES RELACIONADAS LOCALES Y/O DEL EXTERIOR | C5: CON PARTES RELACIONADAS LOCALES | D5: Operaciones de activo | I5: CON PARTES RELACIONADAS LOCALES_Operaciones de activo_ | K5: =SUMIF(BC!$E$6:$E$347,$A5,BC!$K$6:$K$347) -> 0 | L5: =SUMIF(#REF!,$A5,#REF!)+SUMIF(#REF!,$A5,#REF!) -> #REF! | M5: =SUMIF(#REF!,Casilleros!$A5,#REF!)+SUMIF(#REF!,Casilleros!$A5,#REF!)+SUMIF(#REF!,$A5,#REF!) -> #REF! | N5: =SUMIF(#REF!,$A5,#REF!) -> #REF! | O5: =SUMIF(#REF!,$A5,#REF!)+SUMIF(#REF!,$A5,#REF!) -> #REF! | P5: =IFERROR(VLOOKUP($A5,#REF!,2,FALSE),0) -> 0 | Q5: =SUM(K5:P5) -> #REF!
A6: 004 | B6: OPERACIONES CON PARTES RELACIONADAS LOCALES Y/O DEL EXTERIOR | C6: CON PARTES RELACIONADAS LOCALES | D6: Operaciones de pasivo | I6: CON PARTES RELACIONADAS LOCALES_Operaciones de pasivo_ | K6: =SUMIF(BC!$E$6:$E$347,$A6,BC!$K$6:$K$347) -> 0 | L6: =SUMIF(#REF!,$A6,#REF!)+SUMIF(#REF!,$A6,#REF!) -> #REF! | M6: =SUMIF(#REF!,Casilleros!$A6,#REF!)+SUMIF(#REF!,Casilleros!$A6,#REF!)+SUMIF(#REF!,$A6,#REF!) -> #REF! | N6: =SUMIF(#REF!,$A6,#REF!) -> #REF! | O6: =SUMIF(#REF!,$A6,#REF!)+SUMIF(#REF!,$A6,#REF!) -> #REF! | P6: =IFERROR(VLOOKUP($A6,#REF!,2,FALSE),0) -> 0 | Q6: =SUM(K6:P6) -> #REF!
A7: 005 | B7: OPERACIONES CON PARTES RELACIONADAS LOCALES Y/O DEL EXTERIOR | C7: CON PARTES RELACIONADAS LOCALES | D7: Operaciones de ingreso | I7: CON PARTES RELACIONADAS LOCALES_Operaciones de ingreso_ | K7: =SUMIF(BC!$E$6:$E$347,$A7,BC!$K$6:$K$347) -> 0 | L7: =SUMIF(#REF!,$A7,#REF!)+SUMIF(#REF!,$A7,#REF!) -> #REF! | M7: =SUMIF(#REF!,Casilleros!$A7,#REF!)+SUMIF(#REF!,Casilleros!$A7,#REF!)+SUMIF(#REF!,$A7,#REF!) -> #REF! | N7: =SUMIF(#REF!,$A7,#REF!) -> #REF! | O7: =SUMIF(#REF!,$A7,#REF!)+SUMIF(#REF!,$A7,#REF!) -> #REF! | P7: =IFERROR(VLOOKUP($A7,#REF!,2,FALSE),0) -> 0 | Q7: =SUM(K7:P7) -> #REF!
A8: 006 | B8: OPERACIONES CON PARTES RELACIONADAS LOCALES Y/O DEL EXTERIOR | C8: CON PARTES RELACIONADAS LOCALES | D8: Operaciones de egreso | I8: CON PARTES RELACIONADAS LOCALES_Operaciones de egreso_ | K8: =SUMIF(BC!$E$6:$E$347,$A8,BC!$K$6:$K$347) -> 0 | L8: =SUMIF(#REF!,$A8,#REF!)+SUMIF(#REF!,$A8,#REF!) -> #REF! | M8: =SUMIF(#REF!,Casilleros!$A8,#REF!)+SUMIF(#REF!,Casilleros!$A8,#REF!)+SUMIF(#REF!,$A8,#REF!) -> #REF! | N8: =SUMIF(#REF!,$A8,#REF!) -> #REF! | O8: =SUMIF(#REF!,$A8,#REF!)+SUMIF(#REF!,$A8,#REF!) -> #REF! | P8: =IFERROR(VLOOKUP($A8,#REF!,2,FALSE),0) -> 0 | Q8: =SUM(K8:P8) -> #REF!
A9: 007 | B9: OPERACIONES CON PARTES RELACIONADAS LOCALES Y/O DEL EXTERIOR | C9: CON PARTES RELACIONADAS LOCALES | D9: Operaciones de regalías, servicios técnicos, administrativos, de consultoría y similares | I9: CON PARTES RELACIONADAS LOCALES_Operaciones de regalías, servicios técnicos, administrativos, de consultoría y similares_ | K9: =SUMIF(BC!$E$6:$E$347,$A9,BC!$K$6:$K$347) -> 0 | L9: =SUMIF(#REF!,$A9,#REF!)+SUMIF(#REF!,$A9,#REF!) -> #REF! | M9: =SUMIF(#REF!,Casilleros!$A9,#REF!)+SUMIF(#REF!,Casilleros!$A9,#REF!)+SUMIF(#REF!,$A9,#REF!) -> #REF! | N9: =SUMIF(#REF!,$A9,#REF!) -> #REF! | O9: =SUMIF(#REF!,$A9,#REF!)+SUMIF(#REF!,$A9,#REF!) -> #REF! | P9: =IFERROR(VLOOKUP($A9,#REF!,2,FALSE),0) -> 0 | Q9: =SUM(K9:P9) -> #REF!
A10: 008 | B10: OPERACIONES CON PARTES RELACIONADAS LOCALES Y/O DEL EXTERIOR | C10: CON PARTES RELACIONADAS EN PARAÍSOS FISCALES, JURISDICCIONES DE MENOR IMPOSICIÓN Y RÉGIMENES FISCALES PREFERENTES | D10: Operaciones de activo | I10: CON PARTES RELACIONADAS EN PARAÍSOS FISCALES, JURISDICCIONES DE MENOR IMPOSICIÓN Y RÉGIMENES FISCALES PREFERENTES_Operaciones de activo_ | K10: =SUMIF(BC!$E$6:$E$347,$A10,BC!$K$6:$K$347) -> 0 | L10: =SUMIF(#REF!,$A10,#REF!)+SUMIF(#REF!,$A10,#REF!) -> #REF! | M10: =SUMIF(#REF!,Casilleros!$A10,#REF!)+SUMIF(#REF!,Casilleros!$A10,#REF!)+SUMIF(#REF!,$A10,#REF!) -> #REF! | N10: =SUMIF(#REF!,$A10,#REF!) -> #REF! | O10: =SUMIF(#REF!,$A10,#REF!)+SUMIF(#REF!,$A10,#REF!) -> #REF! | P10: =IFERROR(VLOOKUP($A10,#REF!,2,FALSE),0) -> 0 | Q10: =SUM(K10:P10) -> #REF!
A11: 009 | B11: OPERACIONES CON PARTES RELACIONADAS LOCALES Y/O DEL EXTERIOR | C11: CON PARTES RELACIONADAS EN PARAÍSOS FISCALES, JURISDICCIONES DE MENOR IMPOSICIÓN Y RÉGIMENES FISCALES PREFERENTES | D11: Operaciones de pasivo | I11: CON PARTES RELACIONADAS EN PARAÍSOS FISCALES, JURISDICCIONES DE MENOR IMPOSICIÓN Y RÉGIMENES FISCALES PREFERENTES_Operaciones de pasivo_ | K11: =SUMIF(BC!$E$6:$E$347,$A11,BC!$K$6:$K$347) -> 0 | L11: =SUMIF(#REF!,$A11,#REF!)+SUMIF(#REF!,$A11,#REF!) -> #REF! | M11: =SUMIF(#REF!,Casilleros!$A11,#REF!)+SUMIF(#REF!,Casilleros!$A11,#REF!)+SUMIF(#REF!,$A11,#REF!) -> #REF! | N11: =SUMIF(#REF!,$A11,#REF!) -> #REF! | O11: =SUMIF(#REF!,$A11,#REF!)+SUMIF(#REF!,$A11,#REF!) -> #REF! | P11: =IFERROR(VLOOKUP($A11,#REF!,2,FALSE),0) -> 0 | Q11: =SUM(K11:P11) -> #REF!
A12: 010 | B12: OPERACIONES CON PARTES RELACIONADAS LOCALES Y/O DEL EXTERIOR | C12: CON PARTES RELACIONADAS EN PARAÍSOS FISCALES, JURISDICCIONES DE MENOR IMPOSICIÓN Y RÉGIMENES FISCALES PREFERENTES | D12: Operaciones de ingreso | I12: CON PARTES RELACIONADAS EN PARAÍSOS FISCALES, JURISDICCIONES DE MENOR IMPOSICIÓN Y RÉGIMENES FISCALES PREFERENTES_Operaciones de ingreso_ | K12: =SUMIF(BC!$E$6:$E$347,$A12,BC!$K$6:$K$347) -> 0 | L12: =SUMIF(#REF!,$A12,#REF!)+SUMIF(#REF!,$A12,#REF!) -> #REF! | M12: =SUMIF(#REF!,Casilleros!$A12,#REF!)+SUMIF(#REF!,Casilleros!$A12,#REF!)+SUMIF(#REF!,$A12,#REF!) -> #REF! | N12: =SUMIF(#REF!,$A12,#REF!) -> #REF! | O12: =SUMIF(#REF!,$A12,#REF!)+SUMIF(#REF!,$A12,#REF!) -> #REF! | P12: =IFERROR(VLOOKUP($A12,#REF!,2,FALSE),0) -> 0 | Q12: =SUM(K12:P12) -> #REF!
A13: 011 | B13: OPERACIONES CON PARTES RELACIONADAS LOCALES Y/O DEL EXTERIOR | C13: CON PARTES RELACIONADAS EN PARAÍSOS FISCALES, JURISDICCIONES DE MENOR IMPOSICIÓN Y RÉGIMENES FISCALES PREFERENTES | D13: Operaciones de egreso | I13: CON PARTES RELACIONADAS EN PARAÍSOS FISCALES, JURISDICCIONES DE MENOR IMPOSICIÓN Y RÉGIMENES FISCALES PREFERENTES_Operaciones de egreso_ | K13: =SUMIF(BC!$E$6:$E$347,$A13,BC!$K$6:$K$347) -> 0 | L13: =SUMIF(#REF!,$A13,#REF!)+SUMIF(#REF!,$A13,#REF!) -> #REF! | M13: =SUMIF(#REF!,Casilleros!$A13,#REF!)+SUMIF(#REF!,Casilleros!$A13,#REF!)+SUMIF(#REF!,$A13,#REF!) -> #REF! | N13: =SUMIF(#REF!,$A13,#REF!) -> #REF! | O13: =SUMIF(#REF!,$A13,#REF!)+SUMIF(#REF!,$A13,#REF!) -> #REF! | P13: =IFERROR(VLOOKUP($A13,#REF!,2,FALSE),0) -> 0 | Q13: =SUM(K13:P13) -> #REF!
A14: 012 | B14: OPERACIONES CON PARTES RELACIONADAS LOCALES Y/O DEL EXTERIOR | C14: CON PARTES RELACIONADAS EN PARAÍSOS FISCALES, JURISDICCIONES DE MENOR IMPOSICIÓN Y RÉGIMENES FISCALES PREFERENTES | D14: Operaciones de regalías, servicios técnicos, administrativos, de consultoría y similares | I14: CON PARTES RELACIONADAS EN PARAÍSOS FISCALES, JURISDICCIONES DE MENOR IMPOSICIÓN Y RÉGIMENES FISCALES PREFERENTES_Operaciones de regalías, servicios técnicos, administrativos, de consultoría y similares_ | K14: =SUMIF(BC!$E$6:$E$347,$A14,BC!$K$6:$K$347) -> 0 | L14: =SUMIF(#REF!,$A14,#REF!)+SUMIF(#REF!,$A14,#REF!) -> #REF! | M14: =SUMIF(#REF!,Casilleros!$A14,#REF!)+SUMIF(#REF!,Casilleros!$A14,#REF!)+SUMIF(#REF!,$A14,#REF!) -> #REF! | N14: =SUMIF(#REF!,$A14,#REF!) -> #REF! | O14: =SUMIF(#REF!,$A14,#REF!)+SUMIF(#REF!,$A14,#REF!) -> #REF! | P14: =IFERROR(VLOOKUP($A14,#REF!,2,FALSE),0) -> 0 | Q14: =SUM(K14:P14) -> #REF!
A15: 013 | B15: OPERACIONES CON PARTES RELACIONADAS LOCALES Y/O DEL EXTERIOR | C15: CON PARTES RELACIONADAS EN OTRAS JURISDICCIONES O RÉGIMENES DEL EXTERIOR | D15: Operaciones de activo | I15: CON PARTES RELACIONADAS EN OTRAS JURISDICCIONES O RÉGIMENES DEL EXTERIOR_Operaciones de activo_ | K15: =SUMIF(BC!$E$6:$E$347,$A15,BC!$K$6:$K$347) -> 0 | L15: =SUMIF(#REF!,$A15,#REF!)+SUMIF(#REF!,$A15,#REF!) -> #REF! | M15: =SUMIF(#REF!,Casilleros!$A15,#REF!)+SUMIF(#REF!,Casilleros!$A15,#REF!)+SUMIF(#REF!,$A15,#REF!) -> #REF! | N15: =SUMIF(#REF!,$A15,#REF!) -> #REF! | O15: =SUMIF(#REF!,$A15,#REF!)+SUMIF(#REF!,$A15,#REF!) -> #REF! | P15: =IFERROR(VLOOKUP($A15,#REF!,2,FALSE),0) -> 0 | Q15: =SUM(K15:P15) -> #REF!
A16: 014 | B16: OPERACIONES CON PARTES RELACIONADAS LOCALES Y/O DEL EXTERIOR | C16: CON PARTES RELACIONADAS EN OTRAS JURISDICCIONES O RÉGIMENES DEL EXTERIOR | D16: Operaciones de pasivo | I16: CON PARTES RELACIONADAS EN OTRAS JURISDICCIONES O RÉGIMENES DEL EXTERIOR_Operaciones de pasivo_ | K16: =SUMIF(BC!$E$6:$E$347,$A16,BC!$K$6:$K$347) -> 0 | L16: =SUMIF(#REF!,$A16,#REF!)+SUMIF(#REF!,$A16,#REF!) -> #REF! | M16: =SUMIF(#REF!,Casilleros!$A16,#REF!)+SUMIF(#REF!,Casilleros!$A16,#REF!)+SUMIF(#REF!,$A16,#REF!) -> #REF! | N16: =SUMIF(#REF!,$A16,#REF!) -> #REF! | O16: =SUMIF(#REF!,$A16,#REF!)+SUMIF(#REF!,$A16,#REF!) -> #REF! | P16: =IFERROR(VLOOKUP($A16,#REF!,2,FALSE),0) -> 0 | Q16: =SUM(K16:P16) -> #REF!
... A19: 017 | B19: OPERACIONES CON PARTES RELACIONADAS LOCALES Y/O DEL EXTERIOR | C19: CON PARTES RELACIONADAS EN OTRAS JURISDICCIONES O RÉGIMENES DEL EXTERIOR | D19: Operaciones de regalías, servicios técnicos, administrativos, de consultoría y similares | I19: CON PARTES RELACIONADAS EN OTRAS JURISDICCIONES O RÉGIMENES DEL EXTERIOR_Operaciones de regalías, servicios técnicos, administrativos, de consultoría y similares_ | K19: =SUMIF(BC!$E$6:$E$347,$A19,BC!$K$6:$K$347) -> 0 | L19: =SUMIF(#REF!,$A19,#REF!)+SUMIF(#REF!,$A19,#REF!) -> #REF! | M19: =SUMIF(#REF!,Casilleros!$A19,#REF!)+SUMIF(#REF!,Casilleros!$A19,#REF!)+SUMIF(#REF!,$A19,#REF!) -> #REF! | N19: =SUMIF(#REF!,$A19,#REF!) -> #REF! | O19: =SUMIF(#REF!,$A19,#REF!)+SUMIF(#REF!,$A19,#REF!) -> #REF! | P19: =IFERROR(VLOOKUP($A19,#REF!,2,FALSE),0) -> 0 | Q19: =SUM(K19:P19) -> #REF!
A20: 029 | B20: OPERACIONES CON PARTES RELACIONADAS LOCALES Y/O DEL EXTERIOR | C20: TOTAL OPERACIONES CON PARTES RELACIONADAS | I20: TOTAL OPERACIONES CON PARTES RELACIONADAS__ | K20: =SUMIF(BC!$E$6:$E$347,$A20,BC!$K$6:$K$347) -> 0 | L20: =SUMIF(#REF!,$A20,#REF!)+SUMIF(#REF!,$A20,#REF!) -> #REF! | M20: =SUMIF(#REF!,Casilleros!$A20,#REF!)+SUMIF(#REF!,Casilleros!$A20,#REF!)+SUMIF(#REF!,$A20,#REF!) -> #REF! | N20: =SUMIF(#REF!,$A20,#REF!) -> #REF! | O20: =SUMIF(#REF!,$A20,#REF!)+SUMIF(#REF!,$A20,#REF!) -> #REF! | P20: =IFERROR(VLOOKUP($A20,#REF!,2,FALSE),0) -> 0 | Q20: =SUM(K20:P20) -> #REF!
